Workbook

Sheet Cover
A1: FluxMuse Financial Model
A2: AI marketing team & WhatsApp commerce for African SMBs | Fluxmuse Pty Ltd
A4: Version | B4: v3 (current offer: 9 tiers, no trials, R25M seed test)
A5: Model date | B5: 2026-10-05
A6: Horizon | B6: 60 months: Oct 2026 - Sep 2031 (FY1-FY5, fiscal year Oct-Sep). Month 1 = Oct 2026
A7: Currency | B7: ZAR (R); US$ at R18.50 = US$1 (input on Assumptions)
A8: Active scenario | B8: =Assumptions!$B$6
A9: Disclaimer | B9: Forward-looking projections. FluxMuse has no paying customers yet; every volume and rate is an assumption to replace with live data. Red-flagged inputs need founder confirmation.
A11: Headline (live formulas, selected scenario) | C11: FY1 | D11: FY2 | E11: FY3 | F11: FY4 | G11: FY5
A12: Total revenue (net of launch discounts) | C12: =Annual_Summary!$C$16 | D12: =Annual_Summary!$D$16 | E12: =Annual_Summary!$E$16 | F12: =Annual_Summary!$F$16 | G12: =Annual_Summary!$G$16
A13: EBITDA | C13: =Annual_Summary!$C$51 | D13: =Annual_Summary!$D$51 | E13: =Annual_Summary!$E$51 | F13: =Annual_Summary!$F$51 | G13: =Annual_Summary!$G$51
A14: EBITDA margin | C14: =Annual_Summary!$C$52 | D14: =Annual_Summary!$D$52 | E14: =Annual_Summary!$E$52 | F14: =Annual_Summary!$F$52 | G14: =Annual_Summary!$G$52
A15: Paying workspaces (end of FY) | C15: =Annual_Summary!$C$87 | D15: =Annual_Summary!$D$87 | E15: =Annual_Summary!$E$87 | F15: =Annual_Summary!$F$87 | G15: =Annual_Summary!$G$87
A16: Subscription ARR | C16: =Annual_Summary!$C$106 | D16: =Annual_Summary!$D$106 | E16: =Annual_Summary!$E$106 | F16: =Annual_Summary!$F$106 | G16: =Annual_Summary!$G$106
A17: Closing cash | C17: =Annual_Summary!$C$60 | D17: =Annual_Summary!$D$60 | E17: =Annual_Summary!$E$60 | F17: =Annual_Summary!$F$60 | G17: =Annual_Summary!$G$60
A18: Headcount (end of FY) | C18: =Annual_Summary!$C$112 | D18: =Annual_Summary!$D$112 | E18: =Annual_Summary!$E$112 | F18: =Annual_Summary!$F$112 | G18: =Annual_Summary!$G$112
A19: Founding Member discount cost | C19: =Annual_Summary!$C$21 | D19: =Annual_Summary!$D$21 | E19: =Annual_Summary!$E$21 | F19: =Annual_Summary!$F$21 | G19: =Annual_Summary!$G$21
A20: Active Free users (end of FY) | C20: =Annual_Summary!$C$101 | D20: =Annual_Summary!$D$101 | E20: =Annual_Summary!$E$101 | F20: =Annual_Summary!$F$101 | G20: =Annual_Summary!$G$101
A22: Constraint check & key outputs (live formulas, selected scenario)
A23: Profitable on the R25M seed alone? | C23: =Cash_Flow!$B$68
A24: EBITDA break-even (first month) | C24: =Cash_Flow!$B$46
A25: EBITDA break-even (sustained) | C25: =Cash_Flow!$B$48
A26: Operating cash flow positive (first month) | C26: =Cash_Flow!$B$50
A27: Operating cash flow positive (sustained) | C27: =Cash_Flow!$B$52
A28: Minimum closing cash from the seed month on | C28: =Cash_Flow!$B$56
A29: Month of minimum post-seed cash | C29: =Cash_Flow!$B$58
A30: Minimum-cash buffer | C30: =Cash_Flow!$B$63
A31: Shortfall vs buffer | C31: =Cash_Flow!$B$65
A32: Pre-seed bridge required | C32: =Cash_Flow!$B$62
A33: Nigeria launch | C33: =Cash_Flow!$B$77
A34: Kenya launch | C34: =Cash_Flow!$B$79
A35: Ghana launch | C35: =Cash_Flow!$B$81
A36: Rest of Africa (USD) launch | C36: =Cash_Flow!$B$83
A38: Changes from v2 (11 Sep 2026 model) and why
A39: Tiers | B39: 5 tiers -> the live 9: Free R0, Nano R149, Micro R289, Starter R499, Growth R1,999, Scale R4,999, Corporate R6,999, Agency R9,999, Custom (from R19,999). Local NGN/KES/GHS/USD prices from tier_regional_prices. Annual = 10x monthly.
A40: No trials, no pilot | B40: 14-day trial and the 12-brand pilot removed. Paid plans start with payment. A small first group is set up by hand from Oct 2026 (4 a month to Jan 2027) [[CONFIRM]]. South Africa sells from Oct 2026.
A41: Free plan | B41: Sign-ups either pay at once (Solo 5%, SME 8%) or join Free. Active Free users upgrade at 0.5% a month or go dormant at 10% a month. Free AI cost at the live 60 credits a month [[CONFIRM]].
A42: Segments | B42: Solo: Nano 45% / Micro 40% / Starter 15%. SMEs: Starter 40% / Growth 50% / Scale 10%. Corporate is a new inbound line. Agencies on partner wholesale R6,999. Upgrade chains Nano -> Micro -> Starter and Starter -> Growth -> Scale [[CONFIRM]].
A43: Founding Member | B43: 30% off the first 2 monthly bills, South Africa only, Oct 2026 to Mar 2027 (proposed end) [[CONFIRM]]. Old 1 Dec 2026 - 31 Jan 2027 window, NG/KE/GH windows, annual bonus months and pilot 50% pricing removed.
A44: Markets | B44: South Africa only until NG/KE/GH checkout is live. Plan months moved later: Nigeria Apr 2028, Kenya Jul 2028, Ghana Oct 2028, Rest of Africa (USD) May 2029 [[CONFIRM]]. BW/NA still off.
...

Sheet Assumptions
A1: Assumptions
A2: Every driver of the model. Blue on yellow = input. Black = formula. Red source text = [[CONFIRM]] / founder decision pending.
A4: Driver | B4: Live value | C4: Unit | D4: Conservative | E4: Base | F4: Upside | G4: Source / rationale
A6: Active scenario (select) | B6: Base | C6: list | G6: Choose Conservative / Base / Upside. Every scenario driver below uses CHOOSE on this index.
A7: Scenario index (1 = Conservative, 2 = Base, 3 = Upside) | B7: =MATCH($B$6,$D$4:$F$4,0)
A9: General, funding & tax
A10: FX rate | B10: 18.5 | C10: ZAR per US$ | G10: Facts file §2: R18.50 = US$1 (planning rate; live cost rate was R16.43 on 25 Sep 2026)
A11: SA corporate income tax rate | B11: 0.27 | C11: % | G11: SARS 27%. Applied only once cumulative EBITDA is positive (assessed-loss simplification).
A12: Opening cash (1 Oct 2026) | B12: 500000 | C12: R | G12: [[CONFIRM]] founder to confirm cash in bank at 1 Oct 2026; default R500k
A13: Seed raise | B13: 25000000 | C13: R | G13: Facts file §7: Seed R25M (≈US$1.35M). Must reach profitability alone (founder, 2026-09-11)
A14: Seed lands in model month # | B14: 5 | C14: month # | G14: [[CONFIRM]] Month 5 = Feb 2027 (unchanged from v2; no pilot results now gate the close)
A15: Minimum-cash buffer (closing cash must stay above this from the seed month on) | B15: 3000000 | C15: R | G15: Founder constraint: never below R3.0M after the seed lands
A16: Include Series A? (1 = yes, 0 = no) | B16: 0 | C16: switch | G16: OFF in every scenario. Optional acceleration only, not needed for survival
A17: Series A amount (optional acceleration, if switched on) | B17: 0 | C17: R | G17: Default 0 (founder: no Series A in Base or Conservative)
A18: Series A lands in model month # | B18: 30 | C18: month # | G18: Month 30 = Mar 2029 (illustrative)
A19: VAT: Fluxmuse (Pty) Ltd is not VAT-registered. List prices are the amounts charged; revenue is booked as charged with no VAT gross-up or deduction.
A20: Launch, first group set up by hand & lean pre-seed mode (no trials, no pilot)
A21: First group: paying businesses set up by hand each month | B21: 4 | C21: workspaces / month | G21: [[CONFIRM]] Founders onboard a small first group by hand (CURRENT_OFFER §4); no pilot cohort exists
A22: First group: last month # of hand set-up | B22: 4 | C22: month # | G22: [[CONFIRM]] Month 4 = Jan 2027 (Oct 2026 - Jan 2027, until the seed lands)
A23: First group: share that are Solo entrepreneurs (rest SMEs) | B23: 0.5 | C23: % | G23: [[CONFIRM]] Each takes its segment's tier mix; agencies come through the partner channel
A24: First group: hand set-up cost while it runs | B24: 10000 | C24: R / month | G24: [[CONFIRM]] Onboarding visits, set-up time, WhatsApp/AI usage (replaces the R15k pilot cost)
A25: Hosting base before the seed (lean mode) | B25: 15000 | C25: R / month | G25: Supabase/Vercel at early scale (ASSUMPTION)
A26: Overheads before the seed (accounting, banking, Meta/legal minimum) | B26: 15000 | C26: R / month | G26: Lean mode replaces fixed G&A and the legal retainer until the seed lands
A27: Lean mode (months before the seed): founders only, no paid marketing, no office/travel; hiring, brand, partner and legal budgets start in the seed month.
A28: Sensitivity & option levers (leave at defaults for the scenarios)
A29: New sign-up volume multiplier | B29: 1 | C29: x | G29: Scales self-serve sign-ups in every market; Sensitivity sheet
A30: Churn sensitivity multiplier | B30: 1 | C30: x | G30: Multiplies all churn; Sensitivity sheet
A31: Launch discount option (1 = Founding Member, 2 = None) | B31: 1 | C31: option | G31: Founding Member live since 1 Oct 2026 (CURRENT_OFFER §1); None is a sensitivity only
A32: Founding Member: discount on the first 2 monthly bills | B32: 0.3 | C32: % off | G32: CURRENT_OFFER §1: 30% off the first two monthly billing cycles, South African sign-ups. Not modelled on Agency, Corporate or Custom
A33: Founding Member: first month # (South Africa) | B33: 1 | C33: month # | G33: Live from Oct 2026 (confirmed 1 Oct 2026)
A34: Founding Member: last month # (South Africa) | B34: 6 | C34: month # | G34: [[CONFIRM]] No end date is set. Proposed: 31 Mar 2027 (6 months, ends a month after the seed lands)
A35: New sign-up uplift while Founding Member runs | B35: 0.2 | C35: % | G35: [[CONFIRM]] +20% paying sign-ups while the offer runs (unchanged from v2; unproven)
A36: Churn of new sign-ups between discounted bill 1 and 2 | B36: 0.08 | C36: % | G36: Used only to size the second discounted bill (ASSUMPTION)
A37: FX shock: ZAR stronger vs NGN/KES/GHS/USD | B37: 0 | C37: % | G37: Sensitivity sets 15%
A38: FX shock starts in month # | B38: 31 | C38: month # | G38: [[CONFIRM]] Month 31 = Apr 2029, after the later NG/KE/GH plan months
A39: Scenario drivers (switched by the selector above: CHOOSE on columns D:F)
A40: Monthly growth in self-serve sign-ups (Free + paid): FY1 | B40: =CHOOSE($B$7,D40,E40,F40) | C40: % m/m | D40: 0.1 | E40: 0.12 | F40: 0.14 | G40: Per market from its launch month; decays as channels mature (unchanged from v2)
A41: Monthly growth in self-serve sign-ups (Free + paid): FY2 | B41: =CHOOSE($B$7,D41,E41,F41) | C41: % m/m | D41: 0.035 | E41: 0.045 | F41: 0.06
A42: Monthly growth in self-serve sign-ups (Free + paid): FY3 | B42: =CHOOSE($B$7,D42,E42,F42) | C42: % m/m | D42: 0.025 | E42: 0.035 | F42: 0.045
A43: Monthly growth in self-serve sign-ups (Free + paid): FY4 | B43: =CHOOSE($B$7,D43,E43,F43) | C43: % m/m | D43: 0.015 | E43: 0.028 | F43: 0.032
...

Sheet Pricing
A1: Pricing
A2: Live prices (subscription_tiers & tier_regional_prices, CURRENT_OFFER §1). ZAR list for South Africa; fixed local price points for NG/KE/GH and USD for the rest of rail-covered Africa, at FX parity. Annual = 10x monthly. No VAT (not VAT-registered). Free (R0) is modelled on Assumptions as a funnel stage.
A4: Tier | B4: ZAR list / month | C4: ZAR annual | D4: ≈ US$ / month (R18.50) | E4: Modelled AI allowance (credits; internal cost input, never quoted) | F4: Founding Member price, first 2 monthly bills (R, South Africa) | G4: Band | H4: NGN / month | I4: KES / month | J4: GHS / month | K4: USD / month (19 USD markets) | L4: Note
A5: Nano | B5: 149 | C5: =B5*Pricing!$B$18 | D5: =B5/Assumptions!$B$10 | E5: 450 | F5: =ROUNDDOWN(B5*(1-Assumptions!$B$32),0) | G5: Small | H5: 12000 | I5: 1199 | J5: 99 | K5: 8 | L5: Small band. 1 brand, 3 channels; side-hustles
A6: Micro | B6: 289 | C6: =B6*Pricing!$B$18 | D6: =B6/Assumptions!$B$10 | E6: 900 | F6: =ROUNDDOWN(B6*(1-Assumptions!$B$32),0) | G6: Small | H6: 24000 | I6: 2299 | J6: 199 | K6: 16 | L6: Small band. 1 brand, 4 channels, 1 WhatsApp number, WhatsApp commerce
A7: Starter | B7: 499 | C7: =B7*Pricing!$B$18 | D7: =B7/Assumptions!$B$10 | E7: 1500 | F7: =ROUNDDOWN(B7*(1-Assumptions!$B$32),0) | G7: Medium | H7: 41000 | I7: 3999 | J7: 339 | K7: 27 | L7: Medium band. 1 brand, 3 channels
A8: Growth | B8: 1999 | C8: =B8*Pricing!$B$18 | D8: =B8/Assumptions!$B$10 | E8: 6500 | F8: =ROUNDDOWN(B8*(1-Assumptions!$B$32),0) | G8: Medium | H8: 165000 | I8: 15999 | J8: 1359 | K8: 109 | L8: Medium band. 3 brands, 15 channels, inbound AI Voice (beta). Credits incl. 500 bonus where voice is not offered
A9: Scale | B9: 4999 | C9: =B9*Pricing!$B$18 | D9: =B9/Assumptions!$B$10 | E9: 15500 | F9: =ROUNDDOWN(B9*(1-Assumptions!$B$32),0) | G9: Medium | H9: 413000 | I9: 39999 | J9: 3399 | K9: 269 | L9: Medium band. 10 brands, 40 channels, in+out AI Voice (beta). Credits incl. 2,000 bonus (cost-equivalent of outbound voice minutes)
A10: Corporate | B10: 6999 | C10: =B10*Pricing!$B$18 | D10: =B10/Assumptions!$B$10 | E10: 0 | F10: Not modelled | G10: Enterprise | H10: 579000 | I10: 56999 | J10: 4799 | K10: 379 | L10: Enterprise band. 25 brands, 60 channels, BYOC: AI on the customer's own keys, so no AI credit cost to FluxMuse
A11: Agency | B11: 9999 | C11: =B11*Pricing!$B$18 | D11: =B11/Assumptions!$B$10 | E11: 0 | F11: Not modelled | G11: Enterprise | H11: 829000 | I11: 80999 | J11: 6799 | K11: 539 | L11: Enterprise band. Unlimited brands, 80 channels, BYOC, white-label, multi-client; own keys
A12: Custom | B12: 19999 | C12: =B12*Pricing!$B$18 | D12: =B12/Assumptions!$B$10 | E12: 0 | F12: Not modelled | G12: Enterprise | H12: 1650000 | I12: 161000 | J12: 13600 | K12: 1099 | L12: Custom, by consultation. Modelled at 'from R19,999' [[CONFIRM]]; own keys
A13: Partner wholesale: Agency tier -30% | B13: 6999 | C13: =B13*Pricing!$B$18 | D13: =B13/Assumptions!$B$10 | E13: =E11 | F13: Does not stack | G13: Enterprise | H13: 579000 | I13: 56999 | J13: 4799 | K13: 379 | L13: CURRENT_OFFER §1 (confirmed 1 Oct 2026): partners buy Agency at 30% off R9,999 = R6,999. Local wholesale = Corporate local price points [[CONFIRM]]. Referral commission: undecided, not modelled.
A15: Pricing drivers
A16: Annual price escalator (applied each 1 Oct, all markets) | B16: 0.06 | C16: % / year | D16: CPI-linked list-price increase (ASSUMPTION)
A17: Share of subscriptions on annual billing | B17: 0.25 | C17: % | D17: Annual = 10x monthly (unchanged from v2)
A18: Months charged on an annual plan | B18: 10 | C18: months | D18: CURRENT_OFFER §1: annual = 10x monthly
A19: Effective price factor from annual-billing mix | B19: =1-Pricing!$B$17*(12-Pricing!$B$18)/12 | C19: x | D19: Formula: 1 - annual share x (12 - months charged) / 12
A20: Share of agency-segment customers on partner wholesale pricing | B20: 1 | C20: % | D20: CURRENT_OFFER §1 (1 Oct 2026): partners buy Agency at 30% off list (R6,999); default 100% of agency customers
A22: FX: price-setting rates, depreciation vs ZAR and the quarterly repricing policy (depreciation rates are ASSUMPTIONS)
A23: NGN per R1 at price-setting (Sept 2026) | B23: 82.83 | C23: NGN per ZAR | D23: Facts file §2 mid-market rate
A24: KES per R1 at price-setting | B24: 8.07 | C24: KES per ZAR | D24: Facts file §2
A25: GHS per R1 at price-setting | B25: 0.68 | C25: GHS per ZAR | D25: Facts file §2
A26: Annual depreciation of NGN vs ZAR | B26: -0.1 | C26: % / year | D26: ASSUMPTION
A27: Annual depreciation of KES vs ZAR | B27: -0.03 | C27: % / year | D27: ASSUMPTION
A28: Annual depreciation of GHS vs ZAR | B28: -0.08 | C28: % / year | D28: ASSUMPTION
A29: Annual depreciation of USD vs ZAR | B29: 0 | C29: % / year | D29: ASSUMPTION (USD markets)
A30: Repricing trigger: drift in ZAR value of local prices | B30: 0.1 | C30: % | D30: Facts file §2: reprice if FX moves more than ±10%
A31: Quarterly repricing policy on? (1 = yes) | B31: 1 | C31: switch | D31: Reviewed each quarter; new price applies one quarter after the drift is observed
A33: ZAR value of each market's monthly price at price-setting FX (formulas; used by Revenue_Build, then x FX value factor after drift & repricing)
A34: Tier (R / month) | B34: South Africa | C34: Nigeria | D34: Kenya | E34: Ghana | F34: Rest of Africa (USD) | G34: Botswana & Namibia
A35: Nano | B35: =$B$5 | C35: =$H$5/$B$23 | D35: =$I$5/$B$24 | E35: =$J$5/$B$25 | F35: =$K$5*Assumptions!$B$10 | G35: =$B$5
A36: Micro | B36: =$B$6 | C36: =$H$6/$B$23 | D36: =$I$6/$B$24 | E36: =$J$6/$B$25 | F36: =$K$6*Assumptions!$B$10 | G36: =$B$6
A37: Starter | B37: =$B$7 | C37: =$H$7/$B$23 | D37: =$I$7/$B$24 | E37: =$J$7/$B$25 | F37: =$K$7*Assumptions!$B$10 | G37: =$B$7
A38: Growth | B38: =$B$8 | C38: =$H$8/$B$23 | D38: =$I$8/$B$24 | E38: =$J$8/$B$25 | F38: =$K$8*Assumptions!$B$10 | G38: =$B$8
A39: Scale | B39: =$B$9 | C39: =$H$9/$B$23 | D39: =$I$9/$B$24 | E39: =$J$9/$B$25 | F39: =$K$9*Assumptions!$B$10 | G39: =$B$9
A40: Corporate | B40: =$B$10 | C40: =$H$10/$B$23 | D40: =$I$10/$B$24 | E40: =$J$10/$B$25 | F40: =$K$10*Assumptions!$B$10 | G40: =$B$10
A41: Agency | B41: =$B$11 | C41: =$H$11/$B$23 | D41: =$I$11/$B$24 | E41: =$J$11/$B$25 | F41: =$K$11*Assumptions!$B$10 | G41: =$B$11
A42: Custom | B42: =$B$12 | C42: =$H$12/$B$23 | D42: =$I$12/$B$24 | E42: =$J$12/$B$25 | F42: =$K$12*Assumptions!$B$10 | G42: =$B$12
A43: Partner wholesale (Agency -30%) | B43: =$B$13 | C43: =$H$13/$B$23 | D43: =$I$13/$B$24 | E43: =$J$13/$B$25 | F43: =$K$13*Assumptions!$B$10 | G43: =$B$13

Sheet Revenue_Build
A1: Revenue Build
A2: Monthly, Oct 2026 - Sep 2031. Launch gates, FX & repricing, sign-ups, Free plan funnel, acquisition by market & segment with the marketing cap, cohorts, gross -> discounts -> net revenue.
A3: Month # | B3: Unit | C3: 1 | D3: 2 | E3: 3 | F3: 4 | G3: 5 | H3: 6 | I3: 7 | J3: 8 | K3: 9 | L3: 10 | M3: 11 | N3: 12 | O3: 13 | P3: 14 | Q3: 15 | R3: 16 | S3: 17 | T3: 18 | U3: 19 | V3: 20 | W3: 21 | X3: 22 | Y3: 23 | Z3: 24 | AA3: 25 | AB3: 26 | AC3: 27 | AD3: 28 | AE3: 29 | AF3: 30 | AG3: 31 | AH3: 32 | AI3: 33 | AJ3: 34 | AK3: 35 | AL3: 36 | AM3: 37 | AN3: 38 | AO3: 39 | AP3: 40 | AQ3: 41 | AR3: 42 | AS3: 43 | AT3: 44 | AU3: 45 | AV3: 46 | AW3: 47 | AX3: 48 | AY3: 49 | AZ3: 50 | BA3: 51 | BB3: 52 | BC3: 53 | BD3: 54 | BE3: 55 | BF3: 56 | BG3: 57 | BH3: 58 | BI3: 59 | BJ3: 60
A4: Month | C4: Oct 2026 | D4: Nov 2026 | E4: Dec 2026 | F4: Jan 2027 | G4: Feb 2027 | H4: Mar 2027 | I4: Apr 2027 | J4: May 2027 | K4: Jun 2027 | L4: Jul 2027 | M4: Aug 2027 | N4: Sep 2027 | O4: Oct 2027 | P4: Nov 2027 | Q4: Dec 2027 | R4: Jan 2028 | S4: Feb 2028 | T4: Mar 2028 | U4: Apr 2028 | V4: May 2028 | W4: Jun 2028 | X4: Jul 2028 | Y4: Aug 2028 | Z4: Sep 2028 | AA4: Oct 2028 | AB4: Nov 2028 | AC4: Dec 2028 | AD4: Jan 2029 | AE4: Feb 2029 | AF4: Mar 2029 | AG4: Apr 2029 | AH4: May 2029 | AI4: Jun 2029 | AJ4: Jul 2029 | AK4: Aug 2029 | AL4: Sep 2029 | AM4: Oct 2029 | AN4: Nov 2029 | AO4: Dec 2029 | AP4: Jan 2030 | AQ4: Feb 2030 | AR4: Mar 2030 | AS4: Apr 2030 | AT4: May 2030 | AU4: Jun 2030 | AV4: Jul 2030 | AW4: Aug 2030 | AX4: Sep 2030 | AY4: Oct 2030 | AZ4: Nov 2030 | BA4: Dec 2030 | BB4: Jan 2031 | BC4: Feb 2031 | BD4: Mar 2031 | BE4: Apr 2031 | BF4: May 2031 | BG4: Jun 2031 | BH4: Jul 2031 | BI4: Aug 2031 | BJ4: Sep 2031
A5: Fiscal year (Oct-Sep) | C5: 1 | D5: 1 | E5: 1 | F5: 1 | G5: 1 | H5: 1 | I5: 1 | J5: 1 | K5: 1 | L5: 1 | M5: 1 | N5: 1 | O5: 2 | P5: 2 | Q5: 2 | R5: 2 | S5: 2 | T5: 2 | U5: 2 | V5: 2 | W5: 2 | X5: 2 | Y5: 2 | Z5: 2 | AA5: 3 | AB5: 3 | AC5: 3 | AD5: 3 | AE5: 3 | AF5: 3 | AG5: 3 | AH5: 3 | AI5: 3 | AJ5: 3 | AK5: 3 | AL5: 3 | AM5: 4 | AN5: 4 | AO5: 4 | AP5: 4 | AQ5: 4 | AR5: 4 | AS5: 4 | AT5: 4 | AU5: 4 | AV5: 4 | AW5: 4 | AX5: 4 | AY5: 5 | AZ5: 5 | BA5: 5 | BB5: 5 | BC5: 5 | BD5: 5 | BE5: 5 | BF5: 5 | BG5: 5 | BH5: 5 | BI5: 5 | BJ5: 5
A7: Timeline: lean pre-seed mode, first group set up by hand, previous-month MRR (drives every gate and cap)
A8: Seed has landed (1) / lean pre-seed mode (0) | B8: flag | C8: =IF(C$3>=Assumptions!$B$14,1,0) | D8: =IF(D$3>=Assumptions!$B$14,1,0) | E8: =IF(E$3>=Assumptions!$B$14,1,0) | F8: =IF(F$3>=Assumptions!$B$14,1,0) | G8: =IF(G$3>=Assumptions!$B$14,1,0) | H8: =IF(H$3>=Assumptions!$B$14,1,0) | I8: =IF(I$3>=Assumptions!$B$14,1,0) | J8: =IF(J$3>=Assumptions!$B$14,1,0) | ... BJ8: =IF(BJ$3>=Assumptions!$B$14,1,0)
A9: First group being set up by hand (paying from day one) | B9: flag | C9: =IF(C$3<=Assumptions!$B$22,1,0) | D9: =IF(D$3<=Assumptions!$B$22,1,0) | E9: =IF(E$3<=Assumptions!$B$22,1,0) | F9: =IF(F$3<=Assumptions!$B$22,1,0) | G9: =IF(G$3<=Assumptions!$B$22,1,0) | H9: =IF(H$3<=Assumptions!$B$22,1,0) | I9: =IF(I$3<=Assumptions!$B$22,1,0) | J9: =IF(J$3<=Assumptions!$B$22,1,0) | ... BJ9: =IF(BJ$3<=Assumptions!$B$22,1,0)
A10: Net subscription MRR, previous month | B10: R | C10: =0 | D10: =C486 | E10: =D486 | F10: =E486 | G10: =F486 | H10: =G486 | I10: =H486 | J10: =I486 | K10: =J486 | ... BJ10: =BI486
A12: Market launches: decision needs month >= plan + shift - 2, the seed, and MRR >= gate; launch 2 months after decision
A13: Live: South Africa | B13: flag | C13: =IF(C$3>=Assumptions!$B$57,1,0) | D13: =IF(D$3>=Assumptions!$B$57,1,0) | E13: =IF(E$3>=Assumptions!$B$57,1,0) | F13: =IF(F$3>=Assumptions!$B$57,1,0) | G13: =IF(G$3>=Assumptions!$B$57,1,0) | H13: =IF(H$3>=Assumptions!$B$57,1,0) | I13: =IF(I$3>=Assumptions!$B$57,1,0) | J13: =IF(J$3>=Assumptions!$B$57,1,0) | ... BJ13: =IF(BJ$3>=Assumptions!$B$57,1,0)
A14: Launch decided (country lead hired): Nigeria | B14: flag | C14: =IF(AND(Assumptions!$B$59=1,C$3>=Assumptions!$B$60+Assumptions!$B$48-2,C$3>=Assumptions!$B$14,C10>=Assumptions!$B$61*Assumptions!$B$51),1,0) | D14: =IF(OR(C14=1,AND(Assumptions!$B$59=1,D$3>=Assumptions!$B$60+Assumptions!$B$48-2,D$3>=Assumptions!$B$14,D10>=Assumptions!$B$61*Assumptions!$B$51)),1,0) | E14: =IF(OR(D14=1,AND(Assumptions!$B$59=1,E$3>=Assumptions!$B$60+Assumptions!$B$48-2,E$3>=Assumptions!$B$14,E10>=Assumptions!$B$61*Assumptions!$B$51)),1,0) | F14: =IF(OR(E14=1,AND(Assumptions!$B$59=1,F$3>=Assumptions!$B$60+Assumptions!$B$48-2,F$3>=Assumptions!$B$14,F10>=Assumptions!$B$61*Assumptions!$B$51)),1,0) | G14: =IF(OR(F14=1,AND(Assumptions!$B$59=1,G$3>=Assumptions!$B$60+Assumptions!$B$48-2,G$3>=Assumptions!$B$14,G10>=Assumptions!$B$61*Assumptions!$B$51)),1,0) | H14: =IF(OR(G14=1,AND(Assumptions!$B$59=1,H$3>=Assumptions!$B$60+Assumptions!$B$48-2,H$3>=Assumptions!$B$14,H10>=Assumptions!$B$61*Assumptions!$B$51)),1,0) | I14: =IF(OR(H14=1,AND(Assumptions!$B$59=1,I$3>=Assumptions!$B$60+Assumptions!$B$48-2,I$3>=Assumptions!$B$14,I10>=Assumptions!$B$61*Assumptions!$B$51)),1,0) | J14: =IF(OR(I14=1,AND(Assumptions!$B$59=1,J$3>=Assumptions!$B$60+Assumptions!$B$48-2,J$3>=Assumptions!$B$14,J10>=Assumptions!$B$61*Assumptions!$B$51)),1,0) | K14: =IF(OR(J14=1,AND(Assumptions!$B$59=1,K$3>=Assumptions!$B$60+Assumptions!$B$48-2,K$3>=Assumptions!$B$14,K10>=Assumptions!$B$61*Assumptions!$B$51)),1,0) | ... BJ14: =IF(OR(BI14=1,AND(Assumptions!$B$59=1,BJ$3>=Assumptions!$B$60+Assumptions!$B$48-2,BJ$3>=Assumptions!$B$14,BJ10>=Assumptions!$B$61*Assumptions!$B$51)),1,0)
A15: Live: Nigeria | B15: flag | C15: =0 | D15: =0 | E15: =C14 | F15: =D14 | G15: =E14 | H15: =F14 | I15: =G14 | J15: =H14 | K15: =I14 | L15: =J14 | ... BJ15: =BH14
A16: Launch decided (country lead hired): Kenya | B16: flag | C16: =IF(AND(Assumptions!$B$69=1,C$3>=Assumptions!$B$70+Assumptions!$B$48-2,C$3>=Assumptions!$B$14,C10>=Assumptions!$B$71*Assumptions!$B$51),1,0) | D16: =IF(OR(C16=1,AND(Assumptions!$B$69=1,D$3>=Assumptions!$B$70+Assumptions!$B$48-2,D$3>=Assumptions!$B$14,D10>=Assumptions!$B$71*Assumptions!$B$51)),1,0) | E16: =IF(OR(D16=1,AND(Assumptions!$B$69=1,E$3>=Assumptions!$B$70+Assumptions!$B$48-2,E$3>=Assumptions!$B$14,E10>=Assumptions!$B$71*Assumptions!$B$51)),1,0) | F16: =IF(OR(E16=1,AND(Assumptions!$B$69=1,F$3>=Assumptions!$B$70+Assumptions!$B$48-2,F$3>=Assumptions!$B$14,F10>=Assumptions!$B$71*Assumptions!$B$51)),1,0) | G16: =IF(OR(F16=1,AND(Assumptions!$B$69=1,G$3>=Assumptions!$B$70+Assumptions!$B$48-2,G$3>=Assumptions!$B$14,G10>=Assumptions!$B$71*Assumptions!$B$51)),1,0) | H16: =IF(OR(G16=1,AND(Assumptions!$B$69=1,H$3>=Assumptions!$B$70+Assumptions!$B$48-2,H$3>=Assumptions!$B$14,H10>=Assumptions!$B$71*Assumptions!$B$51)),1,0) | I16: =IF(OR(H16=1,AND(Assumptions!$B$69=1,I$3>=Assumptions!$B$70+Assumptions!$B$48-2,I$3>=Assumptions!$B$14,I10>=Assumptions!$B$71*Assumptions!$B$51)),1,0) | J16: =IF(OR(I16=1,AND(Assumptions!$B$69=1,J$3>=Assumptions!$B$70+Assumptions!$B$48-2,J$3>=Assumptions!$B$14,J10>=Assumptions!$B$71*Assumptions!$B$51)),1,0) | K16: =IF(OR(J16=1,AND(Assumptions!$B$69=1,K$3>=Assumptions!$B$70+Assumptions!$B$48-2,K$3>=Assumptions!$B$14,K10>=Assumptions!$B$71*Assumptions!$B$51)),1,0) | ... BJ16: =IF(OR(BI16=1,AND(Assumptions!$B$69=1,BJ$3>=Assumptions!$B$70+Assumptions!$B$48-2,BJ$3>=Assumptions!$B$14,BJ10>=Assumptions!$B$71*Assumptions!$B$51)),1,0)
A17: Live: Kenya | B17: flag | C17: =0 | D17: =0 | E17: =C16 | F17: =D16 | G17: =E16 | H17: =F16 | I17: =G16 | J17: =H16 | K17: =I16 | L17: =J16 | ... BJ17: =BH16
A18: Launch decided (country lead hired): Ghana | B18: flag | C18: =IF(AND(Assumptions!$B$79=1,C$3>=Assumptions!$B$80+Assumptions!$B$48-2,C$3>=Assumptions!$B$14,C10>=Assumptions!$B$81*Assumptions!$B$51),1,0) | D18: =IF(OR(C18=1,AND(Assumptions!$B$79=1,D$3>=Assumptions!$B$80+Assumptions!$B$48-2,D$3>=Assumptions!$B$14,D10>=Assumptions!$B$81*Assumptions!$B$51)),1,0) | E18: =IF(OR(D18=1,AND(Assumptions!$B$79=1,E$3>=Assumptions!$B$80+Assumptions!$B$48-2,E$3>=Assumptions!$B$14,E10>=Assumptions!$B$81*Assumptions!$B$51)),1,0) | F18: =IF(OR(E18=1,AND(Assumptions!$B$79=1,F$3>=Assumptions!$B$80+Assumptions!$B$48-2,F$3>=Assumptions!$B$14,F10>=Assumptions!$B$81*Assumptions!$B$51)),1,0) | G18: =IF(OR(F18=1,AND(Assumptions!$B$79=1,G$3>=Assumptions!$B$80+Assumptions!$B$48-2,G$3>=Assumptions!$B$14,G10>=Assumptions!$B$81*Assumptions!$B$51)),1,0) | H18: =IF(OR(G18=1,AND(Assumptions!$B$79=1,H$3>=Assumptions!$B$80+Assumptions!$B$48-2,H$3>=Assumptions!$B$14,H10>=Assumptions!$B$81*Assumptions!$B$51)),1,0) | I18: =IF(OR(H18=1,AND(Assumptions!$B$79=1,I$3>=Assumptions!$B$80+Assumptions!$B$48-2,I$3>=Assumptions!$B$14,I10>=Assumptions!$B$81*Assumptions!$B$51)),1,0) | J18: =IF(OR(I18=1,AND(Assumptions!$B$79=1,J$3>=Assumptions!$B$80+Assumptions!$B$48-2,J$3>=Assumptions!$B$14,J10>=Assumptions!$B$81*Assumptions!$B$51)),1,0) | K18: =IF(OR(J18=1,AND(Assumptions!$B$79=1,K$3>=Assumptions!$B$80+Assumptions!$B$48-2,K$3>=Assumptions!$B$14,K10>=Assumptions!$B$81*Assumptions!$B$51)),1,0) | ... BJ18: =IF(OR(BI18=1,AND(Assumptions!$B$79=1,BJ$3>=Assumptions!$B$80+Assumptions!$B$48-2,BJ$3>=Assumptions!$B$14,BJ10>=Assumptions!$B$81*Assumptions!$B$51)),1,0)
A19: Live: Ghana | B19: flag | C19: =0 | D19: =0 | E19: =C18 | F19: =D18 | G19: =E18 | H19: =F18 | I19: =G18 | J19: =H18 | K19: =I18 | L19: =J18 | ... BJ19: =BH18
A20: Launch decided (country lead hired): Rest of Africa (USD) | B20: flag | C20: =IF(AND(Assumptions!$B$89=1,C$3>=Assumptions!$B$90+Assumptions!$B$48-2,C$3>=Assumptions!$B$14,C10>=Assumptions!$B$91*Assumptions!$B$51),1,0) | D20: =IF(OR(C20=1,AND(Assumptions!$B$89=1,D$3>=Assumptions!$B$90+Assumptions!$B$48-2,D$3>=Assumptions!$B$14,D10>=Assumptions!$B$91*Assumptions!$B$51)),1,0) | E20: =IF(OR(D20=1,AND(Assumptions!$B$89=1,E$3>=Assumptions!$B$90+Assumptions!$B$48-2,E$3>=Assumptions!$B$14,E10>=Assumptions!$B$91*Assumptions!$B$51)),1,0) | F20: =IF(OR(E20=1,AND(Assumptions!$B$89=1,F$3>=Assumptions!$B$90+Assumptions!$B$48-2,F$3>=Assumptions!$B$14,F10>=Assumptions!$B$91*Assumptions!$B$51)),1,0) | G20: =IF(OR(F20=1,AND(Assumptions!$B$89=1,G$3>=Assumptions!$B$90+Assumptions!$B$48-2,G$3>=Assumptions!$B$14,G10>=Assumptions!$B$91*Assumptions!$B$51)),1,0) | H20: =IF(OR(G20=1,AND(Assumptions!$B$89=1,H$3>=Assumptions!$B$90+Assumptions!$B$48-2,H$3>=Assumptions!$B$14,H10>=Assumptions!$B$91*Assumptions!$B$51)),1,0) | I20: =IF(OR(H20=1,AND(Assumptions!$B$89=1,I$3>=Assumptions!$B$90+Assumptions!$B$48-2,I$3>=Assumptions!$B$14,I10>=Assumptions!$B$91*Assumptions!$B$51)),1,0) | J20: =IF(OR(I20=1,AND(Assumptions!$B$89=1,J$3>=Assumptions!$B$90+Assumptions!$B$48-2,J$3>=Assumptions!$B$14,J10>=Assumptions!$B$91*Assumptions!$B$51)),1,0) | K20: =IF(OR(J20=1,AND(Assumptions!$B$89=1,K$3>=Assumptions!$B$90+Assumptions!$B$48-2,K$3>=Assumptions!$B$14,K10>=Assumptions!$B$91*Assumptions!$B$51)),1,0) | ... BJ20: =IF(OR(BI20=1,AND(Assumptions!$B$89=1,BJ$3>=Assumptions!$B$90+Assumptions!$B$48-2,BJ$3>=Assumptions!$B$14,BJ10>=Assumptions!$B$91*Assumptions!$B$51)),1,0)
A21: Live: Rest of Africa (USD) | B21: flag | C21: =0 | D21: =0 | E21: =C20 | F21: =D20 | G21: =E20 | H21: =F20 | I21: =G20 | J21: =H20 | K21: =I20 | L21: =J20 | ... BJ21: =BH20
A22: Launch decided (country lead hired): Botswana & Namibia | B22: flag | C22: =IF(AND(Assumptions!$B$97=1,C$3>=Assumptions!$B$98+Assumptions!$B$48-2,C$3>=Assumptions!$B$14,C10>=Assumptions!$B$99*Assumptions!$B$51),1,0) | D22: =IF(OR(C22=1,AND(Assumptions!$B$97=1,D$3>=Assumptions!$B$98+Assumptions!$B$48-2,D$3>=Assumptions!$B$14,D10>=Assumptions!$B$99*Assumptions!$B$51)),1,0) | E22: =IF(OR(D22=1,AND(Assumptions!$B$97=1,E$3>=Assumptions!$B$98+Assumptions!$B$48-2,E$3>=Assumptions!$B$14,E10>=Assumptions!$B$99*Assumptions!$B$51)),1,0) | F22: =IF(OR(E22=1,AND(Assumptions!$B$97=1,F$3>=Assumptions!$B$98+Assumptions!$B$48-2,F$3>=Assumptions!$B$14,F10>=Assumptions!$B$99*Assumptions!$B$51)),1,0) | G22: =IF(OR(F22=1,AND(Assumptions!$B$97=1,G$3>=Assumptions!$B$98+Assumptions!$B$48-2,G$3>=Assumptions!$B$14,G10>=Assumptions!$B$99*Assumptions!$B$51)),1,0) | H22: =IF(OR(G22=1,AND(Assumptions!$B$97=1,H$3>=Assumptions!$B$98+Assumptions!$B$48-2,H$3>=Assumptions!$B$14,H10>=Assumptions!$B$99*Assumptions!$B$51)),1,0) | I22: =IF(OR(H22=1,AND(Assumptions!$B$97=1,I$3>=Assumptions!$B$98+Assumptions!$B$48-2,I$3>=Assumptions!$B$14,I10>=Assumptions!$B$99*Assumptions!$B$51)),1,0) | J22: =IF(OR(I22=1,AND(Assumptions!$B$97=1,J$3>=Assumptions!$B$98+Assumptions!$B$48-2,J$3>=Assumptions!$B$14,J10>=Assumptions!$B$99*Assumptions!$B$51)),1,0) | K22: =IF(OR(J22=1,AND(Assumptions!$B$97=1,K$3>=Assumptions!$B$98+Assumptions!$B$48-2,K$3>=Assumptions!$B$14,K10>=Assumptions!$B$99*Assumptions!$B$51)),1,0) | ... BJ22: =IF(OR(BI22=1,AND(Assumptions!$B$97=1,BJ$3>=Assumptions!$B$98+Assumptions!$B$48-2,BJ$3>=Assumptions!$B$14,BJ10>=Assumptions!$B$99*Assumptions!$B$51)),1,0)
A23: Live: Botswana & Namibia | B23: flag | C23: =0 | D23: =0 | E23: =C22 | F23: =D22 | G23: =E22 | H23: =F22 | I23: =G22 | J23: =H22 | K23: =I22 | L23: =J22 | ... BJ23: =BH22
A24: Launch month: South Africa | B24: flag | C24: =C13-0 | D24: =D13-C13 | E24: =E13-D13 | F24: =F13-E13 | G24: =G13-F13 | H24: =H13-G13 | I24: =I13-H13 | J24: =J13-I13 | K24: =K13-J13 | ... BJ24: =BJ13-BI13
A25: Launch month: Nigeria | B25: flag | C25: =C15-0 | D25: =D15-C15 | E25: =E15-D15 | F25: =F15-E15 | G25: =G15-F15 | H25: =H15-G15 | I25: =I15-H15 | J25: =J15-I15 | K25: =K15-J15 | ... BJ25: =BJ15-BI15
A26: Launch month: Kenya | B26: flag | C26: =C17-0 | D26: =D17-C17 | E26: =E17-D17 | F26: =F17-E17 | G26: =G17-F17 | H26: =H17-G17 | I26: =I17-H17 | J26: =J17-I17 | K26: =K17-J17 | ... BJ26: =BJ17-BI17
A27: Launch month: Ghana | B27: flag | C27: =C19-0 | D27: =D19-C19 | E27: =E19-D19 | F27: =F19-E19 | G27: =G19-F19 | H27: =H19-G19 | I27: =I19-H19 | J27: =J19-I19 | K27: =K19-J19 | ... BJ27: =BJ19-BI19
A28: Launch month: Rest of Africa (USD) | B28: flag | C28: =C21-0 | D28: =D21-C21 | E28: =E21-D21 | F28: =F21-E21 | G28: =G21-F21 | H28: =H21-G21 | I28: =I21-H21 | J28: =J21-I21 | K28: =K21-J21 | ... BJ28: =BJ21-BI21
A29: Launch month: Botswana & Namibia | B29: flag | C29: =C23-0 | D29: =D23-C23 | E29: =E23-D23 | F29: =F23-E23 | G29: =G23-F23 | H29: =H23-G23 | I29: =I23-H23 | J29: =J23-I23 | K29: =K23-J23 | ... BJ29: =BJ23-BI23
A30: Founding Member offer running: South Africa | B30: flag | C30: =IF(AND(Assumptions!$B$31=1,C$3>=Assumptions!$B$33,C$3<=Assumptions!$B$34),C13,0) | D30: =IF(AND(Assumptions!$B$31=1,D$3>=Assumptions!$B$33,D$3<=Assumptions!$B$34),D13,0) | E30: =IF(AND(Assumptions!$B$31=1,E$3>=Assumptions!$B$33,E$3<=Assumptions!$B$34),E13,0) | F30: =IF(AND(Assumptions!$B$31=1,F$3>=Assumptions!$B$33,F$3<=Assumptions!$B$34),F13,0) | G30: =IF(AND(Assumptions!$B$31=1,G$3>=Assumptions!$B$33,G$3<=Assumptions!$B$34),G13,0) | H30: =IF(AND(Assumptions!$B$31=1,H$3>=Assumptions!$B$33,H$3<=Assumptions!$B$34),H13,0) | I30: =IF(AND(Assumptions!$B$31=1,I$3>=Assumptions!$B$33,I$3<=Assumptions!$B$34),I13,0) | J30: =IF(AND(Assumptions!$B$31=1,J$3>=Assumptions!$B$33,J$3<=Assumptions!$B$34),J13,0) | ... BJ30: =IF(AND(Assumptions!$B$31=1,BJ$3>=Assumptions!$B$33,BJ$3<=Assumptions!$B$34),BJ13,0)
A32: FX drift & quarterly repricing (ZAR value of fixed local / USD price points; 1.000 = parity at Sept 2026 rates)
A33: ZAR value of 1 unit of Nigeria currency (index) | B33: x | C33: =(1+Pricing!$B$26)^((C$3-1)/12)*IF(C$3>=Assumptions!$B$38,1/(1+Assumptions!$B$37),1) | D33: =(1+Pricing!$B$26)^((D$3-1)/12)*IF(D$3>=Assumptions!$B$38,1/(1+Assumptions!$B$37),1) | E33: =(1+Pricing!$B$26)^((E$3-1)/12)*IF(E$3>=Assumptions!$B$38,1/(1+Assumptions!$B$37),1) | F33: =(1+Pricing!$B$26)^((F$3-1)/12)*IF(F$3>=Assumptions!$B$38,1/(1+Assumptions!$B$37),1) | G33: =(1+Pricing!$B$26)^((G$3-1)/12)*IF(G$3>=Assumptions!$B$38,1/(1+Assumptions!$B$37),1) | H33: =(1+Pricing!$B$26)^((H$3-1)/12)*IF(H$3>=Assumptions!$B$38,1/(1+Assumptions!$B$37),1) | I33: =(1+Pricing!$B$26)^((I$3-1)/12)*IF(I$3>=Assumptions!$B$38,1/(1+Assumptions!$B$37),1) | J33: =(1+Pricing!$B$26)^((J$3-1)/12)*IF(J$3>=Assumptions!$B$38,1/(1+Assumptions!$B$37),1) | ... BJ33: =(1+Pricing!$B$26)^((BJ$3-1)/12)*IF(BJ$3>=Assumptions!$B$38,1/(1+Assumptions!$B$37),1)
A34: Local price level after repricing: Nigeria | B34: x | C34: =1 | D34: =C34 | E34: =D34 | F34: =IF(AND(Pricing!$B$31=1,MOD(F$3-1,3)=0,ABS(E34*C33-1)>Pricing!$B$30),1/C33,E34) | G34: =IF(AND(Pricing!$B$31=1,MOD(G$3-1,3)=0,ABS(F34*D33-1)>Pricing!$B$30),1/D33,F34) | H34: =IF(AND(Pricing!$B$31=1,MOD(H$3-1,3)=0,ABS(G34*E33-1)>Pricing!$B$30),1/E33,G34) | I34: =IF(AND(Pricing!$B$31=1,MOD(I$3-1,3)=0,ABS(H34*F33-1)>Pricing!$B$30),1/F33,H34) | J34: =IF(AND(Pricing!$B$31=1,MOD(J$3-1,3)=0,ABS(I34*G33-1)>Pricing!$B$30),1/G33,I34) | K34: =IF(AND(Pricing!$B$31=1,MOD(K$3-1,3)=0,ABS(J34*H33-1)>Pricing!$B$30),1/H33,J34) | L34: =IF(AND(Pricing!$B$31=1,MOD(L$3-1,3)=0,ABS(K34*I33-1)>Pricing!$B$30),1/I33,K34) | M34: =IF(AND(Pricing!$B$31=1,MOD(M$3-1,3)=0,ABS(L34*J33-1)>Pricing!$B$30),1/J33,L34) | ... BJ34: =IF(AND(Pricing!$B$31=1,MOD(BJ$3-1,3)=0,ABS(BI34*BG33-1)>Pricing!$B$30),1/BG33,BI34)
A35: ZAR value factor of local prices: Nigeria | B35: x | C35: =C34*C33 | D35: =D34*D33 | E35: =E34*E33 | F35: =F34*F33 | G35: =G34*G33 | H35: =H34*H33 | I35: =I34*I33 | J35: =J34*J33 | ... BJ35: =BJ34*BJ33
A36: ZAR value of 1 unit of Kenya currency (index) | B36: x | C36: =(1+Pricing!$B$27)^((C$3-1)/12)*IF(C$3>=Assumptions!$B$38,1/(1+Assumptions!$B$37),1) | D36: =(1+Pricing!$B$27)^((D$3-1)/12)*IF(D$3>=Assumptions!$B$38,1/(1+Assumptions!$B$37),1) | E36: =(1+Pricing!$B$27)^((E$3-1)/12)*IF(E$3>=Assumptions!$B$38,1/(1+Assumptions!$B$37),1) | F36: =(1+Pricing!$B$27)^((F$3-1)/12)*IF(F$3>=Assumptions!$B$38,1/(1+Assumptions!$B$37),1) | G36: =(1+Pricing!$B$27)^((G$3-1)/12)*IF(G$3>=Assumptions!$B$38,1/(1+Assumptions!$B$37),1) | H36: =(1+Pricing!$B$27)^((H$3-1)/12)*IF(H$3>=Assumptions!$B$38,1/(1+Assumptions!$B$37),1) | I36: =(1+Pricing!$B$27)^((I$3-1)/12)*IF(I$3>=Assumptions!$B$38,1/(1+Assumptions!$B$37),1) | J36: =(1+Pricing!$B$27)^((J$3-1)/12)*IF(J$3>=Assumptions!$B$38,1/(1+Assumptions!$B$37),1) | ... BJ36: =(1+Pricing!$B$27)^((BJ$3-1)/12)*IF(BJ$3>=Assumptions!$B$38,1/(1+Assumptions!$B$37),1)
A37: Local price level after repricing: Kenya | B37: x | C37: =1 | D37: =C37 | E37: =D37 | F37: =IF(AND(Pricing!$B$31=1,MOD(F$3-1,3)=0,ABS(E37*C36-1)>Pricing!$B$30),1/C36,E37) | G37: =IF(AND(Pricing!$B$31=1,MOD(G$3-1,3)=0,ABS(F37*D36-1)>Pricing!$B$30),1/D36,F37) | H37: =IF(AND(Pricing!$B$31=1,MOD(H$3-1,3)=0,ABS(G37*E36-1)>Pricing!$B$30),1/E36,G37) | I37: =IF(AND(Pricing!$B$31=1,MOD(I$3-1,3)=0,ABS(H37*F36-1)>Pricing!$B$30),1/F36,H37) | J37: =IF(AND(Pricing!$B$31=1,MOD(J$3-1,3)=0,ABS(I37*G36-1)>Pricing!$B$30),1/G36,I37) | K37: =IF(AND(Pricing!$B$31=1,MOD(K$3-1,3)=0,ABS(J37*H36-1)>Pricing!$B$30),1/H36,J37) | L37: =IF(AND(Pricing!$B$31=1,MOD(L$3-1,3)=0,ABS(K37*I36-1)>Pricing!$B$30),1/I36,K37) | M37: =IF(AND(Pricing!$B$31=1,MOD(M$3-1,3)=0,ABS(L37*J36-1)>Pricing!$B$30),1/J36,L37) | ... BJ37: =IF(AND(Pricing!$B$31=1,MOD(BJ$3-1,3)=0,ABS(BI37*BG36-1)>Pricing!$B$30),1/BG36,BI37)
A38: ZAR value factor of local prices: Kenya | B38: x | C38: =C37*C36 | D38: =D37*D36 | E38: =E37*E36 | F38: =F37*F36 | G38: =G37*G36 | H38: =H37*H36 | I38: =I37*I36 | J38: =J37*J36 | ... BJ38: =BJ37*BJ36
A39: ZAR value of 1 unit of Ghana currency (index) | B39: x | C39: =(1+Pricing!$B$28)^((C$3-1)/12)*IF(C$3>=Assumptions!$B$38,1/(1+Assumptions!$B$37),1) | D39: =(1+Pricing!$B$28)^((D$3-1)/12)*IF(D$3>=Assumptions!$B$38,1/(1+Assumptions!$B$37),1) | E39: =(1+Pricing!$B$28)^((E$3-1)/12)*IF(E$3>=Assumptions!$B$38,1/(1+Assumptions!$B$37),1) | F39: =(1+Pricing!$B$28)^((F$3-1)/12)*IF(F$3>=Assumptions!$B$38,1/(1+Assumptions!$B$37),1) | G39: =(1+Pricing!$B$28)^((G$3-1)/12)*IF(G$3>=Assumptions!$B$38,1/(1+Assumptions!$B$37),1) | H39: =(1+Pricing!$B$28)^((H$3-1)/12)*IF(H$3>=Assumptions!$B$38,1/(1+Assumptions!$B$37),1) | I39: =(1+Pricing!$B$28)^((I$3-1)/12)*IF(I$3>=Assumptions!$B$38,1/(1+Assumptions!$B$37),1) | J39: =(1+Pricing!$B$28)^((J$3-1)/12)*IF(J$3>=Assumptions!$B$38,1/(1+Assumptions!$B$37),1) | ... BJ39: =(1+Pricing!$B$28)^((BJ$3-1)/12)*IF(BJ$3>=Assumptions!$B$38,1/(1+Assumptions!$B$37),1)
A40: Local price level after repricing: Ghana | B40: x | C40: =1 | D40: =C40 | E40: =D40 | F40: =IF(AND(Pricing!$B$31=1,MOD(F$3-1,3)=0,ABS(E40*C39-1)>Pricing!$B$30),1/C39,E40) | G40: =IF(AND(Pricing!$B$31=1,MOD(G$3-1,3)=0,ABS(F40*D39-1)>Pricing!$B$30),1/D39,F40) | H40: =IF(AND(Pricing!$B$31=1,MOD(H$3-1,3)=0,ABS(G40*E39-1)>Pricing!$B$30),1/E39,G40) | I40: =IF(AND(Pricing!$B$31=1,MOD(I$3-1,3)=0,ABS(H40*F39-1)>Pricing!$B$30),1/F39,H40) | J40: =IF(AND(Pricing!$B$31=1,MOD(J$3-1,3)=0,ABS(I40*G39-1)>Pricing!$B$30),1/G39,I40) | K40: =IF(AND(Pricing!$B$31=1,MOD(K$3-1,3)=0,ABS(J40*H39-1)>Pricing!$B$30),1/H39,J40) | L40: =IF(AND(Pricing!$B$31=1,MOD(L$3-1,3)=0,ABS(K40*I39-1)>Pricing!$B$30),1/I39,K40) | M40: =IF(AND(Pricing!$B$31=1,MOD(M$3-1,3)=0,ABS(L40*J39-1)>Pricing!$B$30),1/J39,L40) | ... BJ40: =IF(AND(Pricing!$B$31=1,MOD(BJ$3-1,3)=0,ABS(BI40*BG39-1)>Pricing!$B$30),1/BG39,BI40)
A41: ZAR value factor of local prices: Ghana | B41: x | C41: =C40*C39 | D41: =D40*D39 | E41: =E40*E39 | F41: =F40*F39 | G41: =G40*G39 | H41: =H40*H39 | I41: =I40*I39 | J41: =J40*J39 | ... BJ41: =BJ40*BJ39
A42: ZAR value of 1 unit of Rest of Africa (USD) currency (index) | B42: x | C42: =(1+Pricing!$B$29)^((C$3-1)/12)*IF(C$3>=Assumptions!$B$38,1/(1+Assumptions!$B$37),1) | D42: =(1+Pricing!$B$29)^((D$3-1)/12)*IF(D$3>=Assumptions!$B$38,1/(1+Assumptions!$B$37),1) | E42: =(1+Pricing!$B$29)^((E$3-1)/12)*IF(E$3>=Assumptions!$B$38,1/(1+Assumptions!$B$37),1) | F42: =(1+Pricing!$B$29)^((F$3-1)/12)*IF(F$3>=Assumptions!$B$38,1/(1+Assumptions!$B$37),1) | G42: =(1+Pricing!$B$29)^((G$3-1)/12)*IF(G$3>=Assumptions!$B$38,1/(1+Assumptions!$B$37),1) | H42: =(1+Pricing!$B$29)^((H$3-1)/12)*IF(H$3>=Assumptions!$B$38,1/(1+Assumptions!$B$37),1) | I42: =(1+Pricing!$B$29)^((I$3-1)/12)*IF(I$3>=Assumptions!$B$38,1/(1+Assumptions!$B$37),1) | J42: =(1+Pricing!$B$29)^((J$3-1)/12)*IF(J$3>=Assumptions!$B$38,1/(1+Assumptions!$B$37),1) | ... BJ42: =(1+Pricing!$B$29)^((BJ$3-1)/12)*IF(BJ$3>=Assumptions!$B$38,1/(1+Assumptions!$B$37),1)
A43: Local price level after repricing: Rest of Africa (USD) | B43: x | C43: =1 | D43: =C43 | E43: =D43 | F43: =IF(AND(Pricing!$B$31=1,MOD(F$3-1,3)=0,ABS(E43*C42-1)>Pricing!$B$30),1/C42,E43) | G43: =IF(AND(Pricing!$B$31=1,MOD(G$3-1,3)=0,ABS(F43*D42-1)>Pricing!$B$30),1/D42,F43) | H43: =IF(AND(Pricing!$B$31=1,MOD(H$3-1,3)=0,ABS(G43*E42-1)>Pricing!$B$30),1/E42,G43) | I43: =IF(AND(Pricing!$B$31=1,MOD(I$3-1,3)=0,ABS(H43*F42-1)>Pricing!$B$30),1/F42,H43) | J43: =IF(AND(Pricing!$B$31=1,MOD(J$3-1,3)=0,ABS(I43*G42-1)>Pricing!$B$30),1/G42,I43) | K43: =IF(AND(Pricing!$B$31=1,MOD(K$3-1,3)=0,ABS(J43*H42-1)>Pricing!$B$30),1/H42,J43) | L43: =IF(AND(Pricing!$B$31=1,MOD(L$3-1,3)=0,ABS(K43*I42-1)>Pricing!$B$30),1/I42,K43) | M43: =IF(AND(Pricing!$B$31=1,MOD(M$3-1,3)=0,ABS(L43*J42-1)>Pricing!$B$30),1/J42,L43) | ... BJ43: =IF(AND(Pricing!$B$31=1,MOD(BJ$3-1,3)=0,ABS(BI43*BG42-1)>Pricing!$B$30),1/BG42,BI43)
...

Sheet Costs
A1: Costs
A2: Monthly MRR-gated headcount plan, COGS (incl. Free plan AI cost) and operating expenses (lean pre-seed mode until the seed lands).
A3: Month # | B3: Unit | C3: 1 | D3: 2 | E3: 3 | F3: 4 | G3: 5 | H3: 6 | I3: 7 | J3: 8 | K3: 9 | L3: 10 | M3: 11 | N3: 12 | O3: 13 | P3: 14 | Q3: 15 | R3: 16 | S3: 17 | T3: 18 | U3: 19 | V3: 20 | W3: 21 | X3: 22 | Y3: 23 | Z3: 24 | AA3: 25 | AB3: 26 | AC3: 27 | AD3: 28 | AE3: 29 | AF3: 30 | AG3: 31 | AH3: 32 | AI3: 33 | AJ3: 34 | AK3: 35 | AL3: 36 | AM3: 37 | AN3: 38 | AO3: 39 | AP3: 40 | AQ3: 41 | AR3: 42 | AS3: 43 | AT3: 44 | AU3: 45 | AV3: 46 | AW3: 47 | AX3: 48 | AY3: 49 | AZ3: 50 | BA3: 51 | BB3: 52 | BC3: 53 | BD3: 54 | BE3: 55 | BF3: 56 | BG3: 57 | BH3: 58 | BI3: 59 | BJ3: 60
A4: Month | C4: Oct 2026 | D4: Nov 2026 | E4: Dec 2026 | F4: Jan 2027 | G4: Feb 2027 | H4: Mar 2027 | I4: Apr 2027 | J4: May 2027 | K4: Jun 2027 | L4: Jul 2027 | M4: Aug 2027 | N4: Sep 2027 | O4: Oct 2027 | P4: Nov 2027 | Q4: Dec 2027 | R4: Jan 2028 | S4: Feb 2028 | T4: Mar 2028 | U4: Apr 2028 | V4: May 2028 | W4: Jun 2028 | X4: Jul 2028 | Y4: Aug 2028 | Z4: Sep 2028 | AA4: Oct 2028 | AB4: Nov 2028 | AC4: Dec 2028 | AD4: Jan 2029 | AE4: Feb 2029 | AF4: Mar 2029 | AG4: Apr 2029 | AH4: May 2029 | AI4: Jun 2029 | AJ4: Jul 2029 | AK4: Aug 2029 | AL4: Sep 2029 | AM4: Oct 2029 | AN4: Nov 2029 | AO4: Dec 2029 | AP4: Jan 2030 | AQ4: Feb 2030 | AR4: Mar 2030 | AS4: Apr 2030 | AT4: May 2030 | AU4: Jun 2030 | AV4: Jul 2030 | AW4: Aug 2030 | AX4: Sep 2030 | AY4: Oct 2030 | AZ4: Nov 2030 | BA4: Dec 2030 | BB4: Jan 2031 | BC4: Feb 2031 | BD4: Mar 2031 | BE4: Apr 2031 | BF4: May 2031 | BG4: Jun 2031 | BH4: Jul 2031 | BI4: Aug 2031 | BJ4: Sep 2031
A5: Fiscal year (Oct-Sep) | C5: 1 | D5: 1 | E5: 1 | F5: 1 | G5: 1 | H5: 1 | I5: 1 | J5: 1 | K5: 1 | L5: 1 | M5: 1 | N5: 1 | O5: 2 | P5: 2 | Q5: 2 | R5: 2 | S5: 2 | T5: 2 | U5: 2 | V5: 2 | W5: 2 | X5: 2 | Y5: 2 | Z5: 2 | AA5: 3 | AB5: 3 | AC5: 3 | AD5: 3 | AE5: 3 | AF5: 3 | AG5: 3 | AH5: 3 | AI5: 3 | AJ5: 3 | AK5: 3 | AL5: 3 | AM5: 4 | AN5: 4 | AO5: 4 | AP5: 4 | AQ5: 4 | AR5: 4 | AS5: 4 | AT5: 4 | AU5: 4 | AV5: 4 | AW5: 4 | AX5: 4 | AY5: 5 | AZ5: 5 | BA5: 5 | BB5: 5 | BC5: 5 | BD5: 5 | BE5: 5 | BF5: 5 | BG5: 5 | BH5: 5 | BI5: 5 | BJ5: 5
A7: Headcount: FTEs by role. Non-founder roles need month >= earliest hire, the seed, and last month's MRR >= gate x multiplier
A8: Founder & CEO (reduced salary) | B8: FTE | C8: =IF(C$3>=Assumptions!$E$223,Assumptions!$D$223,0) | D8: =IF(D$3>=Assumptions!$E$223,Assumptions!$D$223,0) | E8: =IF(E$3>=Assumptions!$E$223,Assumptions!$D$223,0) | F8: =IF(F$3>=Assumptions!$E$223,Assumptions!$D$223,0) | G8: =IF(G$3>=Assumptions!$E$223,Assumptions!$D$223,0) | H8: =IF(H$3>=Assumptions!$E$223,Assumptions!$D$223,0) | I8: =IF(I$3>=Assumptions!$E$223,Assumptions!$D$223,0) | J8: =IF(J$3>=Assumptions!$E$223,Assumptions!$D$223,0) | ... BJ8: =IF(BJ$3>=Assumptions!$E$223,Assumptions!$D$223,0)
A9: CTO / founding engineer (reduced salary) | B9: FTE | C9: =IF(C$3>=Assumptions!$E$224,Assumptions!$D$224,0) | D9: =IF(D$3>=Assumptions!$E$224,Assumptions!$D$224,0) | E9: =IF(E$3>=Assumptions!$E$224,Assumptions!$D$224,0) | F9: =IF(F$3>=Assumptions!$E$224,Assumptions!$D$224,0) | G9: =IF(G$3>=Assumptions!$E$224,Assumptions!$D$224,0) | H9: =IF(H$3>=Assumptions!$E$224,Assumptions!$D$224,0) | I9: =IF(I$3>=Assumptions!$E$224,Assumptions!$D$224,0) | J9: =IF(J$3>=Assumptions!$E$224,Assumptions!$D$224,0) | ... BJ9: =IF(BJ$3>=Assumptions!$E$224,Assumptions!$D$224,0)
A10: Senior full-stack engineers | B10: FTE | C10: =IF(AND(C$3>=Assumptions!$E$225,C$3>=Assumptions!$B$14,Revenue_Build!C10>=Assumptions!$F$225*Assumptions!$B$51),Assumptions!$D$225,0) | D10: =IF(OR(C10>0,AND(D$3>=Assumptions!$E$225,D$3>=Assumptions!$B$14,Revenue_Build!D10>=Assumptions!$F$225*Assumptions!$B$51)),Assumptions!$D$225,0) | E10: =IF(OR(D10>0,AND(E$3>=Assumptions!$E$225,E$3>=Assumptions!$B$14,Revenue_Build!E10>=Assumptions!$F$225*Assumptions!$B$51)),Assumptions!$D$225,0) | F10: =IF(OR(E10>0,AND(F$3>=Assumptions!$E$225,F$3>=Assumptions!$B$14,Revenue_Build!F10>=Assumptions!$F$225*Assumptions!$B$51)),Assumptions!$D$225,0) | G10: =IF(OR(F10>0,AND(G$3>=Assumptions!$E$225,G$3>=Assumptions!$B$14,Revenue_Build!G10>=Assumptions!$F$225*Assumptions!$B$51)),Assumptions!$D$225,0) | H10: =IF(OR(G10>0,AND(H$3>=Assumptions!$E$225,H$3>=Assumptions!$B$14,Revenue_Build!H10>=Assumptions!$F$225*Assumptions!$B$51)),Assumptions!$D$225,0) | I10: =IF(OR(H10>0,AND(I$3>=Assumptions!$E$225,I$3>=Assumptions!$B$14,Revenue_Build!I10>=Assumptions!$F$225*Assumptions!$B$51)),Assumptions!$D$225,0) | J10: =IF(OR(I10>0,AND(J$3>=Assumptions!$E$225,J$3>=Assumptions!$B$14,Revenue_Build!J10>=Assumptions!$F$225*Assumptions!$B$51)),Assumptions!$D$225,0) | K10: =IF(OR(J10>0,AND(K$3>=Assumptions!$E$225,K$3>=Assumptions!$B$14,Revenue_Build!K10>=Assumptions!$F$225*Assumptions!$B$51)),Assumptions!$D$225,0) | ... BJ10: =IF(OR(BI10>0,AND(BJ$3>=Assumptions!$E$225,BJ$3>=Assumptions!$B$14,Revenue_Build!BJ10>=Assumptions!$F$225*Assumptions!$B$51)),Assumptions!$D$225,0)
A11: AI / ML engineer | B11: FTE | C11: =IF(AND(C$3>=Assumptions!$E$226,C$3>=Assumptions!$B$14,Revenue_Build!C10>=Assumptions!$F$226*Assumptions!$B$51),Assumptions!$D$226,0) | D11: =IF(OR(C11>0,AND(D$3>=Assumptions!$E$226,D$3>=Assumptions!$B$14,Revenue_Build!D10>=Assumptions!$F$226*Assumptions!$B$51)),Assumptions!$D$226,0) | E11: =IF(OR(D11>0,AND(E$3>=Assumptions!$E$226,E$3>=Assumptions!$B$14,Revenue_Build!E10>=Assumptions!$F$226*Assumptions!$B$51)),Assumptions!$D$226,0) | F11: =IF(OR(E11>0,AND(F$3>=Assumptions!$E$226,F$3>=Assumptions!$B$14,Revenue_Build!F10>=Assumptions!$F$226*Assumptions!$B$51)),Assumptions!$D$226,0) | G11: =IF(OR(F11>0,AND(G$3>=Assumptions!$E$226,G$3>=Assumptions!$B$14,Revenue_Build!G10>=Assumptions!$F$226*Assumptions!$B$51)),Assumptions!$D$226,0) | H11: =IF(OR(G11>0,AND(H$3>=Assumptions!$E$226,H$3>=Assumptions!$B$14,Revenue_Build!H10>=Assumptions!$F$226*Assumptions!$B$51)),Assumptions!$D$226,0) | I11: =IF(OR(H11>0,AND(I$3>=Assumptions!$E$226,I$3>=Assumptions!$B$14,Revenue_Build!I10>=Assumptions!$F$226*Assumptions!$B$51)),Assumptions!$D$226,0) | J11: =IF(OR(I11>0,AND(J$3>=Assumptions!$E$226,J$3>=Assumptions!$B$14,Revenue_Build!J10>=Assumptions!$F$226*Assumptions!$B$51)),Assumptions!$D$226,0) | K11: =IF(OR(J11>0,AND(K$3>=Assumptions!$E$226,K$3>=Assumptions!$B$14,Revenue_Build!K10>=Assumptions!$F$226*Assumptions!$B$51)),Assumptions!$D$226,0) | ... BJ11: =IF(OR(BI11>0,AND(BJ$3>=Assumptions!$E$226,BJ$3>=Assumptions!$B$14,Revenue_Build!BJ10>=Assumptions!$F$226*Assumptions!$B$51)),Assumptions!$D$226,0)
A12: Product designer (UX) | B12: FTE | C12: =IF(AND(C$3>=Assumptions!$E$227,C$3>=Assumptions!$B$14,Revenue_Build!C10>=Assumptions!$F$227*Assumptions!$B$51),Assumptions!$D$227,0) | D12: =IF(OR(C12>0,AND(D$3>=Assumptions!$E$227,D$3>=Assumptions!$B$14,Revenue_Build!D10>=Assumptions!$F$227*Assumptions!$B$51)),Assumptions!$D$227,0) | E12: =IF(OR(D12>0,AND(E$3>=Assumptions!$E$227,E$3>=Assumptions!$B$14,Revenue_Build!E10>=Assumptions!$F$227*Assumptions!$B$51)),Assumptions!$D$227,0) | F12: =IF(OR(E12>0,AND(F$3>=Assumptions!$E$227,F$3>=Assumptions!$B$14,Revenue_Build!F10>=Assumptions!$F$227*Assumptions!$B$51)),Assumptions!$D$227,0) | G12: =IF(OR(F12>0,AND(G$3>=Assumptions!$E$227,G$3>=Assumptions!$B$14,Revenue_Build!G10>=Assumptions!$F$227*Assumptions!$B$51)),Assumptions!$D$227,0) | H12: =IF(OR(G12>0,AND(H$3>=Assumptions!$E$227,H$3>=Assumptions!$B$14,Revenue_Build!H10>=Assumptions!$F$227*Assumptions!$B$51)),Assumptions!$D$227,0) | I12: =IF(OR(H12>0,AND(I$3>=Assumptions!$E$227,I$3>=Assumptions!$B$14,Revenue_Build!I10>=Assumptions!$F$227*Assumptions!$B$51)),Assumptions!$D$227,0) | J12: =IF(OR(I12>0,AND(J$3>=Assumptions!$E$227,J$3>=Assumptions!$B$14,Revenue_Build!J10>=Assumptions!$F$227*Assumptions!$B$51)),Assumptions!$D$227,0) | K12: =IF(OR(J12>0,AND(K$3>=Assumptions!$E$227,K$3>=Assumptions!$B$14,Revenue_Build!K10>=Assumptions!$F$227*Assumptions!$B$51)),Assumptions!$D$227,0) | ... BJ12: =IF(OR(BI12>0,AND(BJ$3>=Assumptions!$E$227,BJ$3>=Assumptions!$B$14,Revenue_Build!BJ10>=Assumptions!$F$227*Assumptions!$B$51)),Assumptions!$D$227,0)
A13: Full-stack engineers | B13: FTE | C13: =IF(AND(C$3>=Assumptions!$E$228,C$3>=Assumptions!$B$14,Revenue_Build!C10>=Assumptions!$F$228*Assumptions!$B$51),Assumptions!$D$228,0) | D13: =IF(OR(C13>0,AND(D$3>=Assumptions!$E$228,D$3>=Assumptions!$B$14,Revenue_Build!D10>=Assumptions!$F$228*Assumptions!$B$51)),Assumptions!$D$228,0) | E13: =IF(OR(D13>0,AND(E$3>=Assumptions!$E$228,E$3>=Assumptions!$B$14,Revenue_Build!E10>=Assumptions!$F$228*Assumptions!$B$51)),Assumptions!$D$228,0) | F13: =IF(OR(E13>0,AND(F$3>=Assumptions!$E$228,F$3>=Assumptions!$B$14,Revenue_Build!F10>=Assumptions!$F$228*Assumptions!$B$51)),Assumptions!$D$228,0) | G13: =IF(OR(F13>0,AND(G$3>=Assumptions!$E$228,G$3>=Assumptions!$B$14,Revenue_Build!G10>=Assumptions!$F$228*Assumptions!$B$51)),Assumptions!$D$228,0) | H13: =IF(OR(G13>0,AND(H$3>=Assumptions!$E$228,H$3>=Assumptions!$B$14,Revenue_Build!H10>=Assumptions!$F$228*Assumptions!$B$51)),Assumptions!$D$228,0) | I13: =IF(OR(H13>0,AND(I$3>=Assumptions!$E$228,I$3>=Assumptions!$B$14,Revenue_Build!I10>=Assumptions!$F$228*Assumptions!$B$51)),Assumptions!$D$228,0) | J13: =IF(OR(I13>0,AND(J$3>=Assumptions!$E$228,J$3>=Assumptions!$B$14,Revenue_Build!J10>=Assumptions!$F$228*Assumptions!$B$51)),Assumptions!$D$228,0) | K13: =IF(OR(J13>0,AND(K$3>=Assumptions!$E$228,K$3>=Assumptions!$B$14,Revenue_Build!K10>=Assumptions!$F$228*Assumptions!$B$51)),Assumptions!$D$228,0) | ... BJ13: =IF(OR(BI13>0,AND(BJ$3>=Assumptions!$E$228,BJ$3>=Assumptions!$B$14,Revenue_Build!BJ10>=Assumptions!$F$228*Assumptions!$B$51)),Assumptions!$D$228,0)
A14: DevOps / QA engineer | B14: FTE | C14: =IF(AND(C$3>=Assumptions!$E$229,C$3>=Assumptions!$B$14,Revenue_Build!C10>=Assumptions!$F$229*Assumptions!$B$51),Assumptions!$D$229,0) | D14: =IF(OR(C14>0,AND(D$3>=Assumptions!$E$229,D$3>=Assumptions!$B$14,Revenue_Build!D10>=Assumptions!$F$229*Assumptions!$B$51)),Assumptions!$D$229,0) | E14: =IF(OR(D14>0,AND(E$3>=Assumptions!$E$229,E$3>=Assumptions!$B$14,Revenue_Build!E10>=Assumptions!$F$229*Assumptions!$B$51)),Assumptions!$D$229,0) | F14: =IF(OR(E14>0,AND(F$3>=Assumptions!$E$229,F$3>=Assumptions!$B$14,Revenue_Build!F10>=Assumptions!$F$229*Assumptions!$B$51)),Assumptions!$D$229,0) | G14: =IF(OR(F14>0,AND(G$3>=Assumptions!$E$229,G$3>=Assumptions!$B$14,Revenue_Build!G10>=Assumptions!$F$229*Assumptions!$B$51)),Assumptions!$D$229,0) | H14: =IF(OR(G14>0,AND(H$3>=Assumptions!$E$229,H$3>=Assumptions!$B$14,Revenue_Build!H10>=Assumptions!$F$229*Assumptions!$B$51)),Assumptions!$D$229,0) | I14: =IF(OR(H14>0,AND(I$3>=Assumptions!$E$229,I$3>=Assumptions!$B$14,Revenue_Build!I10>=Assumptions!$F$229*Assumptions!$B$51)),Assumptions!$D$229,0) | J14: =IF(OR(I14>0,AND(J$3>=Assumptions!$E$229,J$3>=Assumptions!$B$14,Revenue_Build!J10>=Assumptions!$F$229*Assumptions!$B$51)),Assumptions!$D$229,0) | K14: =IF(OR(J14>0,AND(K$3>=Assumptions!$E$229,K$3>=Assumptions!$B$14,Revenue_Build!K10>=Assumptions!$F$229*Assumptions!$B$51)),Assumptions!$D$229,0) | ... BJ14: =IF(OR(BI14>0,AND(BJ$3>=Assumptions!$E$229,BJ$3>=Assumptions!$B$14,Revenue_Build!BJ10>=Assumptions!$F$229*Assumptions!$B$51)),Assumptions!$D$229,0)
A15: Integrations engineers (social adapters, commerce, CRM) | B15: FTE | C15: =IF(AND(C$3>=Assumptions!$E$230,C$3>=Assumptions!$B$14,Revenue_Build!C10>=Assumptions!$F$230*Assumptions!$B$51),Assumptions!$D$230,0) | D15: =IF(OR(C15>0,AND(D$3>=Assumptions!$E$230,D$3>=Assumptions!$B$14,Revenue_Build!D10>=Assumptions!$F$230*Assumptions!$B$51)),Assumptions!$D$230,0) | E15: =IF(OR(D15>0,AND(E$3>=Assumptions!$E$230,E$3>=Assumptions!$B$14,Revenue_Build!E10>=Assumptions!$F$230*Assumptions!$B$51)),Assumptions!$D$230,0) | F15: =IF(OR(E15>0,AND(F$3>=Assumptions!$E$230,F$3>=Assumptions!$B$14,Revenue_Build!F10>=Assumptions!$F$230*Assumptions!$B$51)),Assumptions!$D$230,0) | G15: =IF(OR(F15>0,AND(G$3>=Assumptions!$E$230,G$3>=Assumptions!$B$14,Revenue_Build!G10>=Assumptions!$F$230*Assumptions!$B$51)),Assumptions!$D$230,0) | H15: =IF(OR(G15>0,AND(H$3>=Assumptions!$E$230,H$3>=Assumptions!$B$14,Revenue_Build!H10>=Assumptions!$F$230*Assumptions!$B$51)),Assumptions!$D$230,0) | I15: =IF(OR(H15>0,AND(I$3>=Assumptions!$E$230,I$3>=Assumptions!$B$14,Revenue_Build!I10>=Assumptions!$F$230*Assumptions!$B$51)),Assumptions!$D$230,0) | J15: =IF(OR(I15>0,AND(J$3>=Assumptions!$E$230,J$3>=Assumptions!$B$14,Revenue_Build!J10>=Assumptions!$F$230*Assumptions!$B$51)),Assumptions!$D$230,0) | K15: =IF(OR(J15>0,AND(K$3>=Assumptions!$E$230,K$3>=Assumptions!$B$14,Revenue_Build!K10>=Assumptions!$F$230*Assumptions!$B$51)),Assumptions!$D$230,0) | ... BJ15: =IF(OR(BI15>0,AND(BJ$3>=Assumptions!$E$230,BJ$3>=Assumptions!$B$14,Revenue_Build!BJ10>=Assumptions!$F$230*Assumptions!$B$51)),Assumptions!$D$230,0)
A16: Product manager | B16: FTE | C16: =IF(AND(C$3>=Assumptions!$E$231,C$3>=Assumptions!$B$14,Revenue_Build!C10>=Assumptions!$F$231*Assumptions!$B$51),Assumptions!$D$231,0) | D16: =IF(OR(C16>0,AND(D$3>=Assumptions!$E$231,D$3>=Assumptions!$B$14,Revenue_Build!D10>=Assumptions!$F$231*Assumptions!$B$51)),Assumptions!$D$231,0) | E16: =IF(OR(D16>0,AND(E$3>=Assumptions!$E$231,E$3>=Assumptions!$B$14,Revenue_Build!E10>=Assumptions!$F$231*Assumptions!$B$51)),Assumptions!$D$231,0) | F16: =IF(OR(E16>0,AND(F$3>=Assumptions!$E$231,F$3>=Assumptions!$B$14,Revenue_Build!F10>=Assumptions!$F$231*Assumptions!$B$51)),Assumptions!$D$231,0) | G16: =IF(OR(F16>0,AND(G$3>=Assumptions!$E$231,G$3>=Assumptions!$B$14,Revenue_Build!G10>=Assumptions!$F$231*Assumptions!$B$51)),Assumptions!$D$231,0) | H16: =IF(OR(G16>0,AND(H$3>=Assumptions!$E$231,H$3>=Assumptions!$B$14,Revenue_Build!H10>=Assumptions!$F$231*Assumptions!$B$51)),Assumptions!$D$231,0) | I16: =IF(OR(H16>0,AND(I$3>=Assumptions!$E$231,I$3>=Assumptions!$B$14,Revenue_Build!I10>=Assumptions!$F$231*Assumptions!$B$51)),Assumptions!$D$231,0) | J16: =IF(OR(I16>0,AND(J$3>=Assumptions!$E$231,J$3>=Assumptions!$B$14,Revenue_Build!J10>=Assumptions!$F$231*Assumptions!$B$51)),Assumptions!$D$231,0) | K16: =IF(OR(J16>0,AND(K$3>=Assumptions!$E$231,K$3>=Assumptions!$B$14,Revenue_Build!K10>=Assumptions!$F$231*Assumptions!$B$51)),Assumptions!$D$231,0) | ... BJ16: =IF(OR(BI16>0,AND(BJ$3>=Assumptions!$E$231,BJ$3>=Assumptions!$B$14,Revenue_Build!BJ10>=Assumptions!$F$231*Assumptions!$B$51)),Assumptions!$D$231,0)
A17: Security & compliance engineer | B17: FTE | C17: =IF(AND(C$3>=Assumptions!$E$232,C$3>=Assumptions!$B$14,Revenue_Build!C10>=Assumptions!$F$232*Assumptions!$B$51),Assumptions!$D$232,0) | D17: =IF(OR(C17>0,AND(D$3>=Assumptions!$E$232,D$3>=Assumptions!$B$14,Revenue_Build!D10>=Assumptions!$F$232*Assumptions!$B$51)),Assumptions!$D$232,0) | E17: =IF(OR(D17>0,AND(E$3>=Assumptions!$E$232,E$3>=Assumptions!$B$14,Revenue_Build!E10>=Assumptions!$F$232*Assumptions!$B$51)),Assumptions!$D$232,0) | F17: =IF(OR(E17>0,AND(F$3>=Assumptions!$E$232,F$3>=Assumptions!$B$14,Revenue_Build!F10>=Assumptions!$F$232*Assumptions!$B$51)),Assumptions!$D$232,0) | G17: =IF(OR(F17>0,AND(G$3>=Assumptions!$E$232,G$3>=Assumptions!$B$14,Revenue_Build!G10>=Assumptions!$F$232*Assumptions!$B$51)),Assumptions!$D$232,0) | H17: =IF(OR(G17>0,AND(H$3>=Assumptions!$E$232,H$3>=Assumptions!$B$14,Revenue_Build!H10>=Assumptions!$F$232*Assumptions!$B$51)),Assumptions!$D$232,0) | I17: =IF(OR(H17>0,AND(I$3>=Assumptions!$E$232,I$3>=Assumptions!$B$14,Revenue_Build!I10>=Assumptions!$F$232*Assumptions!$B$51)),Assumptions!$D$232,0) | J17: =IF(OR(I17>0,AND(J$3>=Assumptions!$E$232,J$3>=Assumptions!$B$14,Revenue_Build!J10>=Assumptions!$F$232*Assumptions!$B$51)),Assumptions!$D$232,0) | K17: =IF(OR(J17>0,AND(K$3>=Assumptions!$E$232,K$3>=Assumptions!$B$14,Revenue_Build!K10>=Assumptions!$F$232*Assumptions!$B$51)),Assumptions!$D$232,0) | ... BJ17: =IF(OR(BI17>0,AND(BJ$3>=Assumptions!$E$232,BJ$3>=Assumptions!$B$14,Revenue_Build!BJ10>=Assumptions!$F$232*Assumptions!$B$51)),Assumptions!$D$232,0)
A18: Payments & data engineers | B18: FTE | C18: =IF(AND(C$3>=Assumptions!$E$233,C$3>=Assumptions!$B$14,Revenue_Build!C10>=Assumptions!$F$233*Assumptions!$B$51),Assumptions!$D$233,0) | D18: =IF(OR(C18>0,AND(D$3>=Assumptions!$E$233,D$3>=Assumptions!$B$14,Revenue_Build!D10>=Assumptions!$F$233*Assumptions!$B$51)),Assumptions!$D$233,0) | E18: =IF(OR(D18>0,AND(E$3>=Assumptions!$E$233,E$3>=Assumptions!$B$14,Revenue_Build!E10>=Assumptions!$F$233*Assumptions!$B$51)),Assumptions!$D$233,0) | F18: =IF(OR(E18>0,AND(F$3>=Assumptions!$E$233,F$3>=Assumptions!$B$14,Revenue_Build!F10>=Assumptions!$F$233*Assumptions!$B$51)),Assumptions!$D$233,0) | G18: =IF(OR(F18>0,AND(G$3>=Assumptions!$E$233,G$3>=Assumptions!$B$14,Revenue_Build!G10>=Assumptions!$F$233*Assumptions!$B$51)),Assumptions!$D$233,0) | H18: =IF(OR(G18>0,AND(H$3>=Assumptions!$E$233,H$3>=Assumptions!$B$14,Revenue_Build!H10>=Assumptions!$F$233*Assumptions!$B$51)),Assumptions!$D$233,0) | I18: =IF(OR(H18>0,AND(I$3>=Assumptions!$E$233,I$3>=Assumptions!$B$14,Revenue_Build!I10>=Assumptions!$F$233*Assumptions!$B$51)),Assumptions!$D$233,0) | J18: =IF(OR(I18>0,AND(J$3>=Assumptions!$E$233,J$3>=Assumptions!$B$14,Revenue_Build!J10>=Assumptions!$F$233*Assumptions!$B$51)),Assumptions!$D$233,0) | K18: =IF(OR(J18>0,AND(K$3>=Assumptions!$E$233,K$3>=Assumptions!$B$14,Revenue_Build!K10>=Assumptions!$F$233*Assumptions!$B$51)),Assumptions!$D$233,0) | ... BJ18: =IF(OR(BI18>0,AND(BJ$3>=Assumptions!$E$233,BJ$3>=Assumptions!$B$14,Revenue_Build!BJ10>=Assumptions!$F$233*Assumptions!$B$51)),Assumptions!$D$233,0)
A19: Engineers (scale-up I) | B19: FTE | C19: =IF(AND(C$3>=Assumptions!$E$234,C$3>=Assumptions!$B$14,Revenue_Build!C10>=Assumptions!$F$234*Assumptions!$B$51),Assumptions!$D$234,0) | D19: =IF(OR(C19>0,AND(D$3>=Assumptions!$E$234,D$3>=Assumptions!$B$14,Revenue_Build!D10>=Assumptions!$F$234*Assumptions!$B$51)),Assumptions!$D$234,0) | E19: =IF(OR(D19>0,AND(E$3>=Assumptions!$E$234,E$3>=Assumptions!$B$14,Revenue_Build!E10>=Assumptions!$F$234*Assumptions!$B$51)),Assumptions!$D$234,0) | F19: =IF(OR(E19>0,AND(F$3>=Assumptions!$E$234,F$3>=Assumptions!$B$14,Revenue_Build!F10>=Assumptions!$F$234*Assumptions!$B$51)),Assumptions!$D$234,0) | G19: =IF(OR(F19>0,AND(G$3>=Assumptions!$E$234,G$3>=Assumptions!$B$14,Revenue_Build!G10>=Assumptions!$F$234*Assumptions!$B$51)),Assumptions!$D$234,0) | H19: =IF(OR(G19>0,AND(H$3>=Assumptions!$E$234,H$3>=Assumptions!$B$14,Revenue_Build!H10>=Assumptions!$F$234*Assumptions!$B$51)),Assumptions!$D$234,0) | I19: =IF(OR(H19>0,AND(I$3>=Assumptions!$E$234,I$3>=Assumptions!$B$14,Revenue_Build!I10>=Assumptions!$F$234*Assumptions!$B$51)),Assumptions!$D$234,0) | J19: =IF(OR(I19>0,AND(J$3>=Assumptions!$E$234,J$3>=Assumptions!$B$14,Revenue_Build!J10>=Assumptions!$F$234*Assumptions!$B$51)),Assumptions!$D$234,0) | K19: =IF(OR(J19>0,AND(K$3>=Assumptions!$E$234,K$3>=Assumptions!$B$14,Revenue_Build!K10>=Assumptions!$F$234*Assumptions!$B$51)),Assumptions!$D$234,0) | ... BJ19: =IF(OR(BI19>0,AND(BJ$3>=Assumptions!$E$234,BJ$3>=Assumptions!$B$14,Revenue_Build!BJ10>=Assumptions!$F$234*Assumptions!$B$51)),Assumptions!$D$234,0)
